Workbook

Sheet netflix_titles
A1: show_id | B1: type | C1: title | D1: date_added | E1: release_year | F1: rating | G1: monthly_code | H1: duration | I1: duration_type
A2: s1 | B2: Movie | C2: Dick Johnson Is Dead | D2: 44464 | E2: 2020 | F2: PG-13 | G2: =TEXT(IFERROR(DATEVALUE(D2), D2), "mmm") -> Sep | H2: 90 | I2: min
A3: s21 | B3: TV Show | C3: Monsters Inside: The 24 Faces of Billy Milligan | D3: 44461 | E3: 2021 | F3: TV-14 | G3: =TEXT(IFERROR(DATEVALUE(D3), D3), "mmm") -> Sep | H3: 1 | I3: Season
A4: s22 | B4: TV Show | C4: Resurrection: Ertugrul | D4: 44461 | E4: 2018 | F4: TV-14 | G4: =TEXT(IFERROR(DATEVALUE(D4), D4), "mmm") -> Sep | H4: 5 | I4: Seasons
A5: s23 | B5: Movie | C5: Avvai Shanmughi | D5: 44460 | E5: 1996 | F5: TV-PG | G5: =TEXT(IFERROR(DATEVALUE(D5), D5), "mmm") -> Sep | H5: 161 | I5: min
A6: s24 | B6: Movie | C6: Go! Go! Cory Carson: Chrissy Takes the Wheel | D6: 44460 | E6: 2021 | F6: TV-Y | G6: =TEXT(IFERROR(DATEVALUE(D6), D6), "mmm") -> Sep | H6: 61 | I6: min
A7: s25 | B7: Movie | C7: Jeans | D7: 44460 | E7: 1998 | F7: TV-14 | G7: =TEXT(IFERROR(DATEVALUE(D7), D7), "mmm") -> Sep | H7: 166 | I7: min
A8: s26 | B8: TV Show | C8: Love on the Spectrum | D8: 44460 | E8: 2021 | F8: TV-14 | G8: =TEXT(IFERROR(DATEVALUE(D8), D8), "mmm") -> Sep | H8: 2 | I8: Seasons
A9: s27 | B9: Movie | C9: Minsara Kanavu | D9: 44460 | E9: 1997 | F9: TV-PG | G9: =TEXT(IFERROR(DATEVALUE(D9), D9), "mmm") -> Sep | H9: 147 | I9: min
A10: s28 | B10: Movie | C10: Grown Ups | D10: 44459 | E10: 2010 | F10: PG-13 | G10: =TEXT(IFERROR(DATEVALUE(D10), D10), "mmm") -> Sep | H10: 103 | I10: min
A11: s29 | B11: Movie | C11: Dark Skies | D11: 44458 | E11: 2013 | F11: PG-13 | G11: =TEXT(IFERROR(DATEVALUE(D11), D11), "mmm") -> Sep | H11: 97 | I11: min
A12: s30 | B12: Movie | C12: Paranoia | D12: 44458 | E12: 2013 | F12: PG-13 | G12: =TEXT(IFERROR(DATEVALUE(D12), D12), "mmm") -> Sep | H12: 106 | I12: min
A13: s31 | B13: Movie | C13: Ankahi Kahaniya | D13: 44456 | E13: 2021 | F13: TV-14 | G13: =TEXT(IFERROR(DATEVALUE(D13), D13), "mmm") -> Sep | H13: 111 | I13: min
... A840: s858 | B840: TV Show | C840: The Neighbor | D840: 44337 | E840: 2021 | F840: TV-MA | G840: =TEXT(IFERROR(DATEVALUE(D840), D840), "mmm") -> May | H840: 2 | I840: Seasons
A841: s859 | B841: Movie | C841: 678 | D841: 44336 | E841: 2009 | F841: TV-14 | G841: =TEXT(IFERROR(DATEVALUE(D841), D841), "mmm") -> May | H841: 99 | I841: min
A842: s860 | B842: Movie | C842: Asmaa | D842: 44336 | E842: 2011 | F842: TV-14 | G842: =TEXT(IFERROR(DATEVALUE(D842), D842), "mmm") -> May | H842: 92 | I842: min
A843: s861 | B843: Movie | C843: Hating Peter Tatchell | D843: 44336 | E843: 2020 | F843: TV-MA | G843: =TEXT(IFERROR(DATEVALUE(D843), D843), "mmm") -> May | H843: 91 | I843: min
A844: s862 | B844: Movie | C844: Little Singham Future mein Satakli | D844: 44336 | E844: 2021 | F844: TV-Y7 | G844: =TEXT(IFERROR(DATEVALUE(D844), D844), "mmm") -> May | H844: 47 | I844: min
A845: s863 | B845: TV Show | C845: Special | D845: 44336 | E845: 2021 | F845: TV-MA | G845: =TEXT(IFERROR(DATEVALUE(D845), D845), "mmm") -> May | H845: 2 | I845: Seasons
A846: s864 | B846: Movie | C846: Spy Kids: All the Time in the World | D846: 44336 | E846: 2011 | F846: PG | G846: =TEXT(IFERROR(DATEVALUE(D846), D846), "mmm") -> May | H846: 88 | I846: min
A847: s865 | B847: Movie | C847: Taxi No. 9211 | D847: 44336 | E847: 2006 | F847: TV-14 | G847: =TEXT(IFERROR(DATEVALUE(D847), D847), "mmm") -> May | H847: 116 | I847: min
A848: s866 | B848: Movie | C848: Sabotage | D848: 44335 | E848: 2014 | F848: R | G848: =TEXT(IFERROR(DATEVALUE(D848), D848), "mmm") -> May | H848: 109 | I848: min
A849: s867 | B849: Movie | C849: Small Town Crime | D849: 44335 | E849: 2017 | F849: R | G849: =TEXT(IFERROR(DATEVALUE(D849), D849), "mmm") -> May | H849: 92 | I849: min
A850: s868 | B850: Movie | C850: The Last Days | D850: 44335 | E850: 1998 | F850: PG-13 | G850: =TEXT(IFERROR(DATEVALUE(D850), D850), "mmm") -> May | H850: 87 | I850: min
A851: s869 | B851: TV Show | C851: The Magic School Bus | D851: 44335 | E851: 1997 | F851: TV-Y | G851: =TEXT(IFERROR(DATEVALUE(D851), D851), "mmm") -> May | H851: 1 | I851: Season
A852: s870 | B852: TV Show | C852: Who Killed Sara? | D852: 44335 | E852: 2021 | F852: TV-MA | G852: =TEXT(IFERROR(DATEVALUE(D852), D852), "mmm") -> May | H852: 2 | I852: Seasons
A853: s871 | B853: Movie | C853: Amy Tan: Unintended Memoir | D853: 44334 | E853: 2021 | F853: TV-14 | G853: =TEXT(IFERROR(DATEVALUE(D853), D853), "mmm") -> May | H853: 101 | I853: min
... A1095: s1113 | B1095: Movie | C1095: Woody Woodpecker | D1095: 44288 | E1095: 2017 | F1095: PG | G1095: =TEXT(IFERROR(DATEVALUE(D1095), D1095), "mmm") -> Apr | H1095: 91 | I1095: min
A1096: s1114 | B1096: Movie | C1096: 2012 | D1096: 44287 | E1096: 2009 | F1096: PG-13 | G1096: =TEXT(IFERROR(DATEVALUE(D1096), D1096), "mmm") -> Apr | H1096: 158 | I1096: min
A1097: s1115 | B1097: Movie | C1097: 3 Idiots | D1097: 44287 | E1097: 2009 | F1097: PG-13 | G1097: =TEXT(IFERROR(DATEVALUE(D1097), D1097), "mmm") -> Apr | H1097: 164 | I1097: min
A1098: s1116 | B1098: Movie | C1098: Ferrari Ki Sawaari | D1098: 44287 | E1098: 2012 | F1098: TV-PG | G1098: =TEXT(IFERROR(DATEVALUE(D1098), D1098), "mmm") -> Apr | H1098: 133 | I1098: min
A1099: s1117 | B1099: TV Show | C1099: Glimpses of a Future | D1099: 44287 | E1099: 2020 | F1099: TV-PG | G1099: =TEXT(IFERROR(DATEVALUE(D1099), D1099), "mmm") -> Apr | H1099: 1 | I1099: Season
A1100: s1118 | B1100: Movie | C1100: Ibrahim a Fate to Define | D1100: 44287 | E1100: 2019 | F1100: TV-PG | G1100: =TEXT(IFERROR(DATEVALUE(D1100), D1100), "mmm") -> Apr | H1100: 75 | I1100: min
A1101: s1119 | B1101: Movie | C1101: Insidious | D1101: 44287 | E1101: 2010 | F1101: PG-13 | G1101: =TEXT(IFERROR(DATEVALUE(D1101), D1101), "mmm") -> Apr | H1101: 103 | I1101: min
A1102: s1120 | B1102: Movie | C1102: Into the Grizzly Maze | D1102: 44287 | E1102: 2015 | F1102: R | G1102: =TEXT(IFERROR(DATEVALUE(D1102), D1102), "mmm") -> Apr | H1102: 90 | I1102: min
A1103: s1121 | B1103: Movie | C1103: Kingsglaive: Final Fantasy XV | D1103: 44287 | E1103: 2016 | F1103: PG-13 | G1103: =TEXT(IFERROR(DATEVALUE(D1103), D1103), "mmm") -> Apr | H1103: 116 | I1103: min
A1104: s1122 | B1104: Movie | C1104: Legally Blonde | D1104: 44287 | E1104: 2001 | F1104: PG-13 | G1104: =TEXT(IFERROR(DATEVALUE(D1104), D1104), "mmm") -> Apr | H1104: 96 | I1104: min
A1105: s1123 | B1105: Movie | C1105: Madam Chief Minister | D1105: 44287 | E1105: 2020 | F1105: TV-14 | G1105: =TEXT(IFERROR(DATEVALUE(D1105), D1105), "mmm") -> Apr | H1105: 121 | I1105: min
A1106: s1124 | B1106: TV Show | C1106: Magical Andes | D1106: 44287 | E1106: 2021 | F1106: TV-G | G1106: =TEXT(IFERROR(DATEVALUE(D1106), D1106), "mmm") -> Apr | H1106: 2 | I1106: Seasons
A1107: s1125 | B1107: Movie | C1107: Maximum Risk | D1107: 44287 | E1107: 1996 | F1107: R | G1107: =TEXT(IFERROR(DATEVALUE(D1107), D1107), "mmm") -> Apr | H1107: 101 | I1107: min
...

Sheet Question & Answer
A1: Practical Exercise
K2: EX1 | N2: EX3 | Q2: EX4 | S2: EX5
A3: 1). Display a count of movies by film duration in a pivot table, sorted by count of movie | K3: type | L3: Movie | N3: type | O3: TV Show | Q3: Release Year | S3: Sum of duration | T3: Column Labels
A4: Ans | Q4: {=_xlfn._xlws.SORT(_xlfn.UNIQUE(netflix_titles!E:E))} -> 1925 | S4: Row Labels | T4: 66 min | U4: 74 min | V4: 84 min | W4: G | X4: NC-17 | Y4: NR | Z4: PG | AA4: PG-13 | AB4: R | AC4: TV-14 | AD4: TV-G | AE4: TV-MA | AF4: TV-PG | AG4: TV-Y | AH4: TV-Y7 | AI4: TV-Y7-FV | AJ4: UR | AK4: (blank) | AL4: Grand Total
K5: Row Labels | L5: Count of Movie | N5: Row Labels | O5: Count of show_id | Q5: 1942 | S5: 1925 | AC5: 1 | AL5: 1
K6: 90 min | L6: 152 | N6: Jan | O6: 202 | Q6: 1943 | S6: 1942 | AC6: 70 | AL6: 70
A7: 2). Sum the duration of movies released between 1990 and 2000 using sumifs. | K7: 93 min | L7: 146 | N7: Feb | O7: 181 | Q7: 1944 | S7: 1943 | AF7: 188 | AL7: 188
A8: Ans | B8: =SUMIFS(netflix_titles!H:H,netflix_titles!E:E,">1990",netflix_titles!E:E,"<2000",netflix_titles!B:B,"Movie") -> 25095 | K8: 94 min | L8: 146 | N8: Mar | O8: 213 | Q8: 1945 | S8: 1944 | AC8: 116 | AF8: 40 | AL8: 156
K9: 97 min | L9: 146 | N9: Apr | O9: 214 | Q9: 1946 | S9: 1945 | AC9: 95 | AE9: 60 | AL9: 155
K10: 91 min | L10: 144 | N10: May | O10: 193 | Q10: 1947 | S10: 1946 | AC10: 1 | AF10: 58 | AL10: 59
A11: 3). Count how many TV shows were added each month, regardless of the year. | K11: 95 min | L11: 137 | N11: Jun | O11: 236 | Q11: 1954 | S11: 1947 | AF11: 42 | AL11: 42
A12: Ans | K12: 96 min | L12: 130 | N12: Jul | O12: 262 | Q12: 1955 | S12: 1954 | AC12: 116 | AD12: 120 | AL12: 236
K13: 92 min | L13: 129 | N13: Aug | O13: 236 | Q13: 1956 | S13: 1955 | AA13: 111 | AC13: 97 | AF13: 93 | AL13: 301
K14: 102 min | L14: 122 | N14: Sep | O14: 239 | Q14: 1958 | S14: 1956 | W14: 98 | AC14: 104 | AL14: 202
A15: 4). Display a unique list of release years. | K15: 98 min | L15: 120 | N15: Oct | O15: 215 | Q15: 1959 | S15: 1958 | W15: 115 | Y15: 108 | AC15: 73 | AL15: 296
A16: Ans | K16: 99 min | L16: 118 | N16: Nov | O16: 207 | Q16: 1960 | S16: 1959 | AC16: 143 | AL16: 143
K17: 88 min | L17: 116 | N17: Dec | O17: 266 | Q17: 1961 | S17: 1960 | AC17: 289 | AF17: 285 | AL17: 574
K18: 101 min | L18: 116 | N18: Grand Total | O18: 2664 | Q18: 1962 | S18: 1961 | AC18: 156 | AL18: 156
A19: 5). Show a pivot table by rating on columns, Release year on rows, sum of duration as value. | K19: 103 min | L19: 114 | Q19: 1963 | S19: 1962 | AB19: 153 | AF19: 348 | AL19: 501
A20: Ans | K20: 106 min | L20: 111 | Q20: 1964 | S20: 1963 | AC20: 4 | AE20: 194 | AL20: 198
K21: 100 min | L21: 108 | Q21: 1965 | S21: 1964 | W21: 173 | AC21: 228 | AL21: 401
K22: 89 min | L22: 106 | Q22: 1966 | S22: 1965 | AA22: 200 | AC22: 103 | AL22: 303
A23: 6). Show the title follwing the idusing xlookup | K23: 104 min | L23: 104 | Q23: 1967 | S23: 1966 | AF23: 116 | AL23: 116
A24: s100 | B24: =_xlfn.XLOOKUP('Question & Answer'!A24,netflix_titles!A:A,netflix_titles!C:C) -> On the Verge | K24: 86 min | L24: 103 | Q24: 1968 | S24: 1967 | AB24: 201 | AC24: 127 | AD24: 8 | AE24: 93 | AL24: 429
A25: s2880 | B25: =_xlfn.XLOOKUP('Question & Answer'!A25,netflix_titles!A:A,netflix_titles!C:C) -> Gbomo Gbomo Express | K25: 105 min | L25: 101 | Q25: 1969 | S25: 1968 | W25: 146 | AA25: 166 | AB25: 137 | AL25: 449
A26: s3330 | B26: =_xlfn.XLOOKUP('Question & Answer'!A26,netflix_titles!A:A,netflix_titles!C:C) -> American Son | K26: 87 min | L26: 101 | Q26: 1970 | S26: 1969 | W26: 128 | AF26: 152 | AL26: 280
K27: 107 min | L27: 98 | Q27: 1971 | S27: 1970 | AE27: 130 | AF27: 66 | AL27: 196
K28: 110 min | L28: 97 | Q28: 1972 | S28: 1971 | W28: 281 | AB28: 137 | AC28: 296 | AL28: 714
K29: 108 min | L29: 87 | Q29: 1973 | S29: 1972 | AB29: 91 | AC29: 115 | AE29: 105 | AF29: 125 | AL29: 436
K30: 116 min | L30: 80 | Q30: 1974 | S30: 1973 | W30: 94 | Y30: 81 | Z30: 89 | AB30: 317 | AC30: 553 | AE30: 97 | AL30: 1231
K31: 112 min | L31: 74 | Q31: 1975 | S31: 1974 | Z31: 112 | AB31: 204 | AC31: 166 | AF31: 104 | AJ31: 103 | AL31: 689
K32: 85 min | L32: 73 | Q32: 1976 | S32: 1975 | Z32: 216 | AC32: 240 | AE32: 197 | AF32: 127 | AL32: 780
K33: 109 min | L33: 69 | Q33: 1977 | S33: 1976 | Z33: 472 | AB33: 98 | AC33: 156 | AE33: 124 | AF33: 292 | AL33: 1142
K34: 113 min | L34: 69 | Q34: 1978 | S34: 1977 | W34: 84 | Z34: 272 | AC34: 172 | AE34: 150 | AF34: 133 | AL34: 811
K35: 111 min | L35: 68 | Q35: 1979 | S35: 1978 | Z35: 226 | AB35: 97 | AD35: 25 | AE35: 172 | AF35: 141 | AL35: 661
K36: 84 min | L36: 67 | Q36: 1980 | S36: 1979 | Z36: 119 | AA36: 100 | AB36: 187 | AC36: 472 | AE36: 210 | AF36: 138 | AL36: 1226
K37: 118 min | L37: 65 | Q37: 1981 | S37: 1980 | Z37: 114 | AB37: 532 | AC37: 550 | AF37: 120 | AL37: 1316
K38: 83 min | L38: 65 | Q38: 1982 | S38: 1981 | Y38: 86 | Z38: 224 | AB38: 209 | AC38: 817 | AE38: 85 | AF38: 92 | AH38: 1 | AL38: 1514
K39: 119 min | L39: 63 | Q39: 1983 | S39: 1982 | Z39: 193 | AB39: 301 | AC39: 988 | AE39: 269 | AF39: 373 | AL39: 2124
K40: 81 min | L40: 62 | Q40: 1984 | S40: 1983 | Z40: 98 | AC40: 710 | AE40: 406 | AL40: 1214
...

Sheet cast
A1: show_id | B1: cast_1 | C1: cast_2 | D1: cast_3 | E1: cast_4 | F1: cast_5 | G1: cast_6 | H1: cast_7 | I1: cast_8 | J1: cast_9 | K1: cast_10 | L1: cast_11 | M1: cast_12 | N1: cast_13 | O1: cast_14 | P1: cast_15 | Q1: cast_16 | R1: cast_17 | S1: cast_18 | T1: cast_19 | U1: cast_20 | V1: cast_21 | W1: cast_22 | X1: cast_23 | Y1: cast_24 | Z1: cast_25 | AA1: cast_26 | AB1: cast_27 | AC1: cast_28 | AD1: cast_29 | AE1: cast_30 | AF1: cast_31 | AG1: cast_32 | AH1: cast_33 | AI1: cast_34 | AJ1: cast_35 | AK1: cast_36 | AL1: cast_37 | AM1: cast_38 | AN1: cast_39 | AO1: cast_40 | AP1: cast_41 | AQ1: cast_42 | AR1: cast_43 | AS1: cast_44 | AT1: cast_45 | AU1: cast_46 | AV1: cast_47 | AW1: cast_48 | AX1: cast_49 | AY1: cast_50
A2: s1
A3: s2 | B3: Ama Qamata | C3: Khosi Ngema | D3: Gail Mabalane | E3: Thabang Molaba | F3: Dillon Windvogel | G3: Natasha Thahane | H3: Arno Greeff | I3: Xolile Tshabalala | J3: Getmore Sithole | K3: Cindy Mahlangu | L3: Ryle De Morny | M3: Greteli Fincham | N3: Sello Maake Ka-Ncube | O3: Odwa Gwanya | P3: Mekaila Mathys | Q3: Sandi Schultz | R3: Duane Williams | S3: Shamilla Miller | T3: Patrick Mofokeng
A4: s3 | B4: Sami Bouajila | C4: Tracy Gotoas | D4: Samuel Jouy | E4: Nabiha Akkari | F4: Sofia Lesaffre | G4: Salim Kechiouche | H4: Noureddine Farihi | I4: Geert Van Rampelberg | J4: Bakary Diombera
A5: s4
A6: s5 | B6: Mayur More | C6: Jitendra Kumar | D6: Ranjan Raj | E6: Alam Khan | F6: Ahsaas Channa | G6: Revathi Pillai | H6: Urvi Singh | I6: Arun Kumar
A7: s6 | B7: Kate Siegel | C7: Zach Gilford | D7: Hamish Linklater | E7: Henry Thomas | F7: Kristin Lehman | G7: Samantha Sloyan | H7: Igby Rigney | I7: Rahul Kohli | J7: Annarah Cymone | K7: Annabeth Gish | L7: Alex Essoe | M7: Rahul Abburi | N7: Matt Biedel | O7: Michael Trucco | P7: Crystal Balint | Q7: Louis Oliver
A8: s7 | B8: Vanessa Hudgens | C8: Kimiko Glenn | D8: James Marsden | E8: Sofia Carson | F8: Liza Koshy | G8: Ken Jeong | H8: Elizabeth Perkins | I8: Jane Krakowski | J8: Michael McKean | K8: Phil LaMarr
A9: s8 | B9: Kofi Ghanaba | C9: Oyafunmike Ogunlano | D9: Alexandra Duah | E9: Nick Medley | F9: Mutabaruka | G9: Afemo Omilami | H9: Reggie Carter | I9: Mzuri
A10: s9 | B10: Mel Giedroyc | C10: Sue Perkins | D10: Mary Berry | E10: Paul Hollywood
A11: s10 | B11: Melissa McCarthy | C11: Chris O'Dowd | D11: Kevin Kline | E11: Timothy Olyphant | F11: Daveed Diggs | G11: Skyler Gisondo | H11: Laura Harrier | I11: Rosalind Chao | J11: Kimberly Quinn | K11: Loretta Devine | L11: Ravi Kapoor
A12: s11
A13: s12 | B13: Sukollawat Kanarot | C13: Sushar Manaying | D13: Pavarit Mongkolpisit | E13: Sahajak Boonthanakit | F13: Suthipongse Thatphithakkul | G13: Bhasaworn Bawronkirati | H13: Daweerit Chullasapya | I13: Waratthaya Wongchayaporn | J13: Kittiphoom Wongpentak | K13: Abhicha Thanachanun | L13: Nophand Boonyai | M13: Kittipong Khamsat | N13: Arisara Wongchalee | O13: Jaytiya Naiwattanakul | P13: Pantipa Arunwattanachai | Q13: Panupan Jantanawong | R13: Kungtap Saelim | S13: Phumphat Chartsuriyakiat | T13: Issara Veranitinunt | U13: Keerati Sivakuae | V13: Panjai Sirisuwan | W13: Supranee Charoenpol | X13: Suda Chuenban | Y13: Visaka Banhansupavat | Z13: Pitchatorn Santinatornkul
A14: s13 | B14: Luna Wedler | C14: Jannis NiewÃ¶hner | D14: Milan Peschel | E14: Edin HasanoviÄ‡ | F14: Anna FialovÃ¡ | G14: Marlon Boess | H14: Victor Boccard | I14: Fleur Geffrier | J14: Aziz Dyab | K14: MÃ©lanie FouchÃ© | L14: Elizaveta MaximovÃ¡
A15: s14 | B15: Klara Castanho | C15: Lucca Picon | D15: JÃºlia Gomes | E15: Marcus Bessa | F15: Kiria Malheiros | G15: Fernanda Concon | H15: Gabriel Lima | I15: Caio Cabral | J15: Leonardo Cidade | K15: Jade Cardozo
A16: s15
A17: s16 | B17: Logan Browning | C17: Brandon P. Bell | D17: DeRon Horton | E17: Antoinette Robertson | F17: John Patrick Amedori | G17: Ashley Blaine Featherson | H17: Marque Richardson | I17: Giancarlo Esposito
A18: s17
A19: s18 | B19: Luis Ernesto Franco | C19: Camila Sodi | D19: Sergio Goyri | E19: Samadhi Zendejas | F19: Eduardo YÃ¡Ã±ez | G19: Sonya Smith | H19: Alejandro Camacho | I19: Azela Robinson | J19: Uriel del Toro | K19: GÃ©raldine BazÃ¡n | L19: Gabriela Roel | M19: Marcus Ornellas
A20: s19 | B20: Freida Pinto | C20: Logan Marshall-Green | D20: Robert John Burke | E20: Megan Elisabeth Kelly | F20: Sarah Minnich | G20: Hayes Hargrove | H20: Mark Sivertsen | I20: Brandon Fierro | J20: Antonio Valles | K20: Clint Obenchain
A21: s20 | B21: Blanca SuÃ¡rez | C21: IvÃ¡n Marcos | D21: Ã“scar Casas | E21: AdriÃ¡n Lastra | F21: Francesc Garrido | G21: Stefan Weinert | H21: Julia MÃ¶ller | I21: Alicia Chojnowski
A22: s21
A23: s22 | B23: Engin Altan DÃ¼zyatan | C23: Serdar GÃ¶khan | D23: HÃ¼lya Darcan | E23: Kaan TaÅŸaner | F23: Esra BilgiÃ§ | G23: Osman Soykut | H23: Serdar Deniz | I23: Cengiz CoÅŸkun | J23: Reshad Strik | K23: Hande SubaÅŸÄ±
A24: s23 | B24: Kamal Hassan | C24: Meena | D24: Gemini Ganesan | E24: Heera Rajgopal | F24: Nassar | G24: S.P. Balasubrahmanyam
A25: s24 | B25: Maisie Benson | C25: Paul Killam | D25: Kerry Gudjohnsen | E25: AC Lim
A26: s25 | B26: Prashanth | C26: Aishwarya Rai Bachchan | D26: Sri Lakshmi | E26: Nassar
A27: s26 | B27: Brooke Satchwell
A28: s27 | B28: Arvind Swamy | C28: Kajol | D28: Prabhu Deva | E28: Nassar | F28: S.P. Balasubrahmanyam | G28: Girish Karnad
A29: s28 | B29: Adam Sandler | C29: Kevin James | D29: Chris Rock | E29: David Spade | F29: Rob Schneider | G29: Salma Hayek | H29: Maria Bello | I29: Maya Rudolph | J29: Colin Quinn | K29: Tim Meadows | L29: Joyce Van Patten
A30: s29 | B30: Keri Russell | C30: Josh Hamilton | D30: J.K. Simmons | E30: Dakota Goyo | F30: Kadan Rockett | G30: L.J. Benet | H30: Rich Hutchman | I30: Myndy Crist | J30: Annie Thurman | K30: Jake Brennan
A31: s30 | B31: Liam Hemsworth | C31: Gary Oldman | D31: Amber Heard | E31: Harrison Ford | F31: Lucas Till | G31: Embeth Davidtz | H31: Julian McMahon | I31: Josh Holloway | J31: Richard Dreyfuss | K31: Angela Sarafyan
A32: s31 | B32: Abhishek Banerjee | C32: Rinku Rajguru | D32: Delzad Hiwale | E32: Kunal Kapoor | F32: Zoya Hussain | G32: Nikhil Dwivedi | H32: Palomi Ghosh
A33: s32 | B33: Lauren Ash | C33: Rory O'Malley | D33: RuPaul Charles | E33: Jill Talley | F33: Ike Barinholtz | G33: Jon Barinholtz | H33: Matthew Craig | I33: Bob Odenkirk | J33: Mike Hagerty | K33: Katie Rich | L33: Chris Witaske
A34: s33 | B34: Asa Butterfield | C34: Gillian Anderson | D34: Ncuti Gatwa | E34: Emma Mackey | F34: Connor Swindells | G34: Kedar Williams-Stirling | H34: Alistair Petrie
A35: s34 | B35: Lee Jung-jae | C35: Park Hae-soo | D35: Wi Ha-jun | E35: Oh Young-soo | F35: Jung Ho-yeon | G35: Heo Sung-tae | H35: Kim Joo-ryoung | I35: Tripathi Anupam | J35: You Seong-joo | K35: Lee You-mi
A36: s35 | B36: Dami Lee | C36: Jason Lee | D36: Bommie Catherine Han | E36: Jennifer Waescher | F36: Nancy Kim
A37: s36 | B37: Adrian Titieni | C37: Elena Purea | D37: Judith State | E37: Valeriu AndriuÈ›Äƒ | F37: Tudor Smoleanu | G37: Virgil Aioanei | H37: Radu Botar | I37: Petronela Grigorescu | J37: Bogdan Nechifor | K37: Cristian Bota
A38: s37 | B38: Gilles Lellouche | C38: Karim Leklou | D38: FranÃ§ois Civil | E38: AdÃ¨le Exarchopoulos | F38: Kenza Fortas | G38: Cyril Lecomte | H38: MichaÃ«l Abiteboul | I38: Idir Azougli | J38: Vincent Darmuzey | K38: Jean-Yves Berteloot
A39: s38 | B39: Antti PÃ¤Ã¤kkÃ¶nen | C39: HeljÃ¤ Heikkinen | D39: Lynne Guaglione | E39: Pasi Ruohonen | F39: Rauno Ahonen
A40: s39 | B40: Billy Magnussen | C40: Ron Yuan | D40: Qu Jingjing | E40: Terry Chen | F40: Vanness Wu | G40: Jin Xing | H40: Philip Ng | I40: Xia Yu | J40: Yu Xia
...

Sheet director
A1: show_id | B1: director_1 | C1: director_2 | D1: director_3 | E1: director_4 | F1: director_5 | G1: director_6 | H1: director_7 | I1: director_8 | J1: director_9 | K1: director_10 | L1: director_11 | M1: director_12 | N1: director_13
A2: s1 | B2: Kirsten Johnson
A3: s2
A4: s3 | B4: Julien Leclercq
A5: s4
A6: s5
A7: s6 | B7: Mike Flanagan
A8: s7 | B8: Robert Cullen | C8: JosÃ© Luis Ucha
A9: s8 | B9: Haile Gerima
A10: s9 | B10: Andy Devonshire
A11: s10 | B11: Theodore Melfi
A12: s11
A13: s12 | B13: Kongkiat Komesiri
A14: s13 | B14: Christian Schwochow
A15: s14 | B15: Bruno Garotti
A16: s15
A17: s16
A18: s17 | B18: Pedro de Echave GarcÃ­a | C18: Pablo AzorÃ­n Williams
A19: s18
A20: s19 | B20: Adam Salky
A21: s20
A22: s21 | B22: Olivier Megaton
A23: s22
A24: s23 | B24: K.S. Ravikumar
A25: s24 | B25: Alex Woo | C25: Stanley Moore
A26: s25 | B26: S. Shankar
A27: s26
A28: s27 | B28: Rajiv Menon
A29: s28 | B29: Dennis Dugan
A30: s29 | B30: Scott Stewart
A31: s30 | B31: Robert Luketic
A32: s31 | B32: Ashwiny Iyer Tiwari | C32: Abhishek Chaubey | D32: Saket Chaudhary
A33: s32
A34: s33
A35: s34
A36: s35
A37: s36 | B37: Daniel Sandu
A38: s37 | B38: CÃ©dric Jimenez
A39: s38
A40: s39 | B40: George Nolfi
...

Sheet listed in
A1: show_id | B1: listed_in_1 | C1: listed_in_2 | D1: listed_in_3
A2: s1 | B2: Documentaries
A3: s2 | B3: International TV Shows | C3: TV Dramas | D3: TV Mysteries
A4: s3 | B4: Crime TV Shows | C4: International TV Shows | D4: TV Action & Adventure
A5: s4 | B5: Docuseries | C5: Reality TV
A6: s5 | B6: International TV Shows | C6: Romantic TV Shows | D6: TV Comedies
A7: s6 | B7: TV Dramas | C7: TV Horror | D7: TV Mysteries
A8: s7 | B8: Children & Family Movies
A9: s8 | B9: Dramas | C9: Independent Movies | D9: International Movies
A10: s9 | B10: British TV Shows | C10: Reality TV
A11: s10 | B11: Comedies | C11: Dramas
A12: s11 | B12: Crime TV Shows | C12: Docuseries | D12: International TV Shows
A13: s12 | B13: Crime TV Shows | C13: International TV Shows | D13: TV Action & Adventure
A14: s13 | B14: Dramas | C14: International Movies
A15: s14 | B15: Children & Family Movies | C15: Comedies
A16: s15 | B16: British TV Shows | C16: Crime TV Shows | D16: Docuseries
A17: s16 | B17: TV Comedies | C17: TV Dramas
A18: s17 | B18: Documentaries | C18: International Movies
A19: s18 | B19: Crime TV Shows | C19: Spanish-Language TV Shows | D19: TV Dramas
A20: s19 | B20: Thrillers
A21: s20 | B21: International TV Shows | C21: Spanish-Language TV Shows | D21: TV Action & Adventure
A22: s21 | B22: Crime TV Shows | C22: Docuseries | D22: International TV Shows
A23: s22 | B23: International TV Shows | C23: TV Action & Adventure | D23: TV Dramas
A24: s23 | B24: Comedies | C24: International Movies
A25: s24 | B25: Children & Family Movies
A26: s25 | B26: Comedies | C26: International Movies | D26: Romantic Movies
A27: s26 | B27: Docuseries | C27: International TV Shows | D27: Reality TV
A28: s27 | B28: Comedies | C28: International Movies | D28: Music & Musicals
A29: s28 | B29: Comedies
A30: s29 | B30: Horror Movies | C30: Sci-Fi & Fantasy
A31: s30 | B31: Thrillers
A32: s31 | B32: Dramas | C32: Independent Movies | D32: International Movies
A33: s32 | B33: TV Comedies
A34: s33 | B34: British TV Shows | C34: International TV Shows | D34: TV Comedies
A35: s34 | B35: International TV Shows | C35: TV Dramas | D35: TV Thrillers
A36: s35 | B36: Kids' TV
A37: s36 | B37: Dramas | C37: International Movies | D37: Thrillers
A38: s37 | B38: Action & Adventure | C38: Dramas | D38: International Movies
A39: s38 | B39: Kids' TV | C39: TV Comedies
A40: s39 | B40: Action & Adventure | C40: Dramas
...

Sheet country
A1: show_id | B1: country_1 | C1: country_2 | D1: country_3 | E1: country_4 | F1: country_5 | G1: country_6 | H1: country_7 | I1: country_8 | J1: country_9 | K1: country_10 | L1: country_11 | M1: country_12
A2: s1 | B2: United States
A3: s2 | B3: South Africa
A4: s3
A5: s4
A6: s5 | B6: India
A7: s6
A8: s7
A9: s8 | B9: United States | C9: Ghana | D9: Burkina Faso | E9: United Kingdom | F9: Germany | G9: Ethiopia
A10: s9 | B10: United Kingdom
A11: s10 | B11: United States
A12: s11
A13: s12
A14: s13 | B14: Germany | C14: Czech Republic
A15: s14
A16: s15
A17: s16 | B17: United States
A18: s17
A19: s18 | B19: Mexico
A20: s19
A21: s20
A22: s21
A23: s22 | B23: Turkey
A24: s23
A25: s24
A26: s25 | B26: India
A27: s26 | B27: Australia
A28: s27
A29: s28 | B29: United States
A30: s29 | B30: United States
A31: s30 | B31: United States | C31: India | D31: France
A32: s31
A33: s32
A34: s33 | B34: United Kingdom
A35: s34
A36: s35
A37: s36
A38: s37
A39: s38 | B39: Finland
A40: s39 | B40: China | C40: Canada | D40: United States
...

Sheet description
A1: show_id | B1: description
A2: s1 | B2: As her father nears the end of his life, filmmaker Kirsten Johnson stages his death in inventive and comical ways to help them both face the inevitable.
A3: s2 | B3: After crossing paths at a party, a Cape Town teen sets out to prove whether a private-school swimming star is her sister who was abducted at birth.
A4: s3 | B4: To protect his family from a powerful drug lord, skilled thief Mehdi and his expert team of robbers are pulled into a violent and deadly turf war.
A5: s4 | B5: Feuds, flirtations and toilet talk go down among the incarcerated women at the Orleans Justice Center in New Orleans on this gritty reality series.
A6: s5 | B6: In a city of coaching centers known to train Indiaâ€™s finest collegiate minds, an earnest but unexceptional student and his friends navigate campus life.
A7: s6 | B7: The arrival of a charismatic young priest brings glorious miracles, ominous mysteries and renewed religious fervor to a dying town desperate to believe.
A8: s7 | B8: Equestria's divided. But a bright-eyed hero believes Earth Ponies, Pegasi and Unicorns should be pals â€” and, hoof to heart, sheâ€™s determined to prove it.
A9: s8 | B9: On a photo shoot in Ghana, an American model slips back in time, becomes enslaved on a plantation and bears witness to the agony of her ancestral past.
A10: s9 | B10: A talented batch of amateur bakers face off in a 10-week competition, whipping up their best dishes in the hopes of being named the U.K.'s best.
A11: s10 | B11: A woman adjusting to life after a loss contends with a feisty bird that's taken over her garden â€” and a husband who's struggling to find a way forward.
A12: s11 | B12: Sicily boasts a bold "Anti-Mafia" coalition. But what happens when those trying to bring down organized crime are accused of being criminals themselves?
... A8808: s8807 | B8808: A scrappy but poor boy worms his way into a tycoon's dysfunctional family, while facing his fear of music and the truth about his past.
